Workbook

Sheet Tabelle1
A1: Handle | B1: Def-Lochung | C1: Maschenlänge und -breite | D1: Material | E1: Stärke | F1: Format | G1: Bild | H1: Datenblatt | I1: Lagerplatz | J1: Untertitel | K1: Preis 1 | L1: Preis 2 | M1: Preis 3 | N1: Preis 4 | O1: Preis 5 | P1: Preis 6 | Q1: Preis 7 | R1: Preis 8 | S1: Preis 9 | T1: Preis 10 | U1: Versand | V1: Artikel-Nr | W1: Material-Gruppe | X1: DIN-Bezeichnung (alt) | Y1: DIN-Bezeichnung (neu) | Z1: SpezifischesGewicht | AA1: Ao, ungelochte Fläche | AB1: Gewicht pro Tafel | AC1: DIN | AD1: Daten 9 | AE1: Daten 10 | AF1: Hinweis
A2: streckmetall-tafelware-8x4x1 | B2: Streckgitter | C2: 8x4x1 | D2: Aluminium | E2: 1,00 mm | F2: Kleinformat (1000 x 2000 mm) | G2: https://cdn.shopify.com/s/files/1/0575/0797/1253/files/Streckmetall_Raute_8x4x1.jpg?v=1723045159 | H2: https://cdn.shopify.com/s/files/1/0575/0797/1253/files/8-4-1.pdf?v=1723206890 | I2: // | J2: (ohne Folie) | K2: 134.4 | L2: 114 | M2: 99 | N2: 83 | O2: 74 | P2: 74 | Q2: 58 | R2: 58 | S2: 58 | T2: 50 | U2: 0 | V2: 12977 | W2: Aluminium ohne Folie | X2: Al 99,5 % hh | Y2: EN AW-1050A H24 | Z2: 2,7 g/cm³ | AA2: 50,00 % | AB2: 2,70 Kg | AC2: 791 | AF2: Ohne besondere Oberflächenbearbeitung.
A3: =VLOOKUP(V3,SVERWEIS!A:B,2,FALSE) -> streckmetall-tafelware-8x4x1 | B3: Streckgitter | C3: 8x4x1 | D3: Aluminium | E3: 1,00 mm | F3: Mittelformat (1250 x 2500 mm) | G3: https://cdn.shopify.com/s/files/1/0575/0797/1253/files/Streckmetall_Raute_8x4x1.jpg?v=1723045159 | H3: https://cdn.shopify.com/s/files/1/0575/0797/1253/files/8-4-1.pdf?v=1723206890 | I3: // | J3: (ohne Folie) | K3: 392 | L3: 207 | M3: 173 | N3: 155 | O3: 120 | P3: 120 | Q3: 101 | R3: 101 | S3: 101 | T3: 89 | U3: 0 | V3: 12978 | W3: Aluminium ohne Folie | X3: Al 99,5 % hh | Y3: EN AW-1050A H24 | Z3: 2,7 g/cm³ | AA3: 50,00 % | AB3: 4,22 Kg | AC3: 791 | AF3: Ohne besondere Oberflächenbearbeitung.
A4: streckmetall-tafelware-8x4x1 | B4: Streckgitter | C4: 8x4x1 | D4: Stahl (verzinkt) | E4: 1,00 mm | F4: Kleinformat (1000 x 2000 mm) | G4: https://cdn.shopify.com/s/files/1/0575/0797/1253/files/Streckmetall_Raute_8x4x1.jpg?v=1723045159 | H4: https://cdn.shopify.com/s/files/1/0575/0797/1253/files/8-4-1.pdf?v=1723206890 | I4: // | K4: 103 | L4: 88 | M4: 77 | N4: 64 | O4: 56 | P4: 56 | Q4: 49 | R4: 49 | S4: 49 | T4: 41 | U4: 0 | V4: 12975 | W4: Sendzimir (verzinkt) | X4: St 02 Z 140 | Y4: DX51D+Z 140 | Z4: 8 g/cm³ | AA4: 50,00 % | AB4: 8,00 Kg | AC4: 791 | AF4: Wir weisen darauf hin, dass diese Zinkauflage im Außenbereich keinen ausreichenden und dauerhaften Korrosionsschutz gewährt.
A5: =VLOOKUP(V5,SVERWEIS!A:B,2,FALSE) -> streckmetall-tafelware-8x4x1 | B5: Streckgitter | C5: 8x4x1 | D5: Stahl (verzinkt) | E5: 1,00 mm | F5: Mittelformat (1250 x 2500 mm) | G5: https://cdn.shopify.com/s/files/1/0575/0797/1253/files/Streckmetall_Raute_8x4x1.jpg?v=1723045159 | H5: https://cdn.shopify.com/s/files/1/0575/0797/1253/files/8-4-1.pdf?v=1723206890 | I5: // | K5: 161 | L5: 120 | M5: 101 | N5: 88 | O5: 77 | P5: 77 | Q5: 65 | R5: 65 | S5: 65 | T5: 57 | U5: 0 | V5: 12976 | W5: Sendzimir (verzinkt) | X5: St 02 Z 140 | Y5: DX51D+Z 140 | Z5: 8 g/cm³ | AA5: 50,00 % | AB5: 12,50 Kg | AC5: 791 | AF5: Wir weisen darauf hin, dass diese Zinkauflage im Außenbereich keinen ausreichenden und dauerhaften Korrosionsschutz gewährt.
A6: streckmetall-tafelware-8x4x1 | B6: Streckgitter | C6: 8x4x1 | D6: Stahl | E6: 1,00 mm | F6: Kleinformat (1000 x 2000 mm) | G6: https://cdn.shopify.com/s/files/1/0575/0797/1253/files/Streckmetall_Raute_8x4x1.jpg?v=1723045159 | H6: https://cdn.shopify.com/s/files/1/0575/0797/1253/files/8-4-1.pdf?v=1723206890 | I6: // | K6: 100 | L6: 86 | M6: 74 | N6: 62 | O6: 54 | P6: 54 | Q6: 47 | R6: 47 | S6: 47 | T6: 41 | U6: 0 | V6: 12973 | W6: Stahl | X6: StW 22 | Y6: DD 11 | Z6: 8 g/cm³ | AA6: 50,00 % | AB6: 8,00 Kg | AC6: 791 | AF6: Ohne besondere Oberflächenbearbeitung.
A7: =VLOOKUP(V7,SVERWEIS!A:B,2,FALSE) -> streckmetall-tafelware-8x4x1 | B7: Streckgitter | C7: 8x4x1 | D7: Stahl | E7: 1,00 mm | F7: Mittelformat (1250 x 2500 mm) | G7: https://cdn.shopify.com/s/files/1/0575/0797/1253/files/Streckmetall_Raute_8x4x1.jpg?v=1723045159 | H7: https://cdn.shopify.com/s/files/1/0575/0797/1253/files/8-4-1.pdf?v=1723206890 | I7: // | K7: 157 | L7: 117 | M7: 98 | N7: 85 | O7: 75 | P7: 75 | Q7: 64 | R7: 64 | S7: 64 | T7: 56 | U7: 0 | V7: 12974 | W7: Stahl | X7: StW 22 | Y7: DD 11 | Z7: 8 g/cm³ | AA7: 50,00 % | AB7: 12,50 Kg | AC7: 791 | AF7: Ohne besondere Oberflächenbearbeitung.
A8: streckmetall-tafelware-8x6x1 | B8: Streckgitter | C8: 8x6x1 | D8: Aluminium | E8: 1,00 mm | F8: Kleinformat (1000 x 2000 mm) | G8: https://cdn.shopify.com/s/files/1/0575/0797/1253/files/Streckmetall_Raute_8x6x1.jpg?v=1723045158 | H8: https://cdn.shopify.com/s/files/1/0575/0797/1253/files/8-6-1.pdf?v=1723206889 | I8: // | J8: (ohne Folie) | K8: 249 | L8: 155 | M8: 131 | N8: 109 | O8: 98 | P8: 98 | Q8: 76 | R8: 76 | S8: 76 | T8: 63 | U8: 0 | V8: 12981 | W8: Aluminium ohne Folie | X8: Al 99,5 % hh | Y8: EN AW-1050A H24 | Z8: 2,7 g/cm³ | AA8: 67,00 % | AB8: 1,78 Kg | AC8: 791 | AF8: Ohne besondere Oberflächenbearbeitung.
A9: =VLOOKUP(V9,SVERWEIS!A:B,2,FALSE) -> streckmetall-tafelware-8x6x1 | B9: Streckgitter | C9: 8x6x1 | D9: Aluminium | E9: 1,00 mm | F9: Mittelformat (1250 x 2500 mm) | G9: https://cdn.shopify.com/s/files/1/0575/0797/1253/files/Streckmetall_Raute_8x6x1.jpg?v=1723045158 | H9: https://cdn.shopify.com/s/files/1/0575/0797/1253/files/8-6-1.pdf?v=1723206889 | I9: // | J9: (ohne Folie) | K9: 389 | L9: 205 | M9: 171 | N9: 153 | O9: 119 | P9: 119 | Q9: 99 | R9: 99 | S9: 99 | T9: 89 | U9: 0 | V9: 12983 | W9: Aluminium ohne Folie | X9: Al 99,5 % hh | Y9: EN AW-1050A H24 | Z9: 2,7 g/cm³ | AA9: 67,00 % | AB9: 2,78 Kg | AC9: 791 | AF9: Ohne besondere Oberflächenbearbeitung.
A10: streckmetall-tafelware-8x6x1 | B10: Streckgitter | C10: 8x6x1 | D10: Stahl | E10: 1,00 mm | F10: Kleinformat (1000 x 2000 mm) | G10: https://cdn.shopify.com/s/files/1/0575/0797/1253/files/Streckmetall_Raute_8x6x1.jpg?v=1723045158 | H10: https://cdn.shopify.com/s/files/1/0575/0797/1253/files/8-6-1.pdf?v=1723206889 | I10: // | K10: 99 | L10: 85 | M10: 73 | N10: 61 | O10: 53 | P10: 53 | Q10: 46 | R10: 46 | S10: 46 | T10: 40 | U10: 0 | V10: 12980 | W10: Stahl | X10: St 12.03 | Y10: DC 01 | Z10: 8 g/cm³ | AA10: 67,00 % | AB10: 5,28 Kg | AC10: 791 | AF10: Ohne besondere Oberflächenbearbeitung.
A11: =VLOOKUP(V11,SVERWEIS!A:B,2,FALSE) -> streckmetall-tafelware-8x6x1 | B11: Streckgitter | C11: 8x6x1 | D11: Stahl | E11: 1,00 mm | F11: Mittelformat (1250 x 2500 mm) | G11: https://cdn.shopify.com/s/files/1/0575/0797/1253/files/Streckmetall_Raute_8x6x1.jpg?v=1723045158 | H11: https://cdn.shopify.com/s/files/1/0575/0797/1253/files/8-6-1.pdf?v=1723206889 | I11: // | K11: 311 | L11: 185 | M11: 136 | N11: 111 | O11: 94 | P11: 94 | Q11: 77 | R11: 77 | S11: 77 | T11: 68 | U11: 0 | V11: 12982 | W11: Stahl | X11: St 12.03 | Y11: DC 01 | Z11: 8 g/cm³ | AA11: 67,00 % | AB11: 8,25 Kg | AC11: 791 | AF11: Ohne besondere Oberflächenbearbeitung.
A12: streckmetall-tafelware-20x10x2 | B12: Streckgitter | C12: 20x10x2 | D12: Aluminium | E12: 1,00 mm | F12: Kleinformat (1000 x 2000 mm) | G12: https://cdn.shopify.com/s/files/1/0575/0797/1253/files/Streckmetall_Raute_20x10x2.jpg?v=1723045158 | H12: https://cdn.shopify.com/s/files/1/0575/0797/1253/files/20-10-2.pdf?v=1723206888 | I12: // | J12: (ohne Folie) | K12: 133 | L12: 113 | M12: 98 | N12: 81 | O12: 73 | P12: 73 | Q12: 56 | R12: 56 | S12: 56 | T12: 48 | U12: 0 | V12: 13036 | W12: Aluminium ohne Folie | X12: Al 99,5 % hh | Y12: EN AW-1050A H24 | Z12: 2,7 g/cm³ | AA12: 60,00 % | AB12: 2,16 Kg | AC12: 791 | AF12: Ohne besondere Oberflächenbearbeitung.
A13: =VLOOKUP(V13,SVERWEIS!A:B,2,FALSE) -> streckmetall-tafelware-20x10x2 | B13: Streckgitter | C13: 20x10x2 | D13: Aluminium | E13: 1,00 mm | F13: Mittelformat (1250 x 2500 mm) | G13: https://cdn.shopify.com/s/files/1/0575/0797/1253/files/Streckmetall_Raute_20x10x2.jpg?v=1723045158 | H13: https://cdn.shopify.com/s/files/1/0575/0797/1253/files/20-10-2.pdf?v=1723206888 | I13: // | J13: (ohne Folie) | K13: 209 | L13: 154 | M13: 128 | N13: 115 | O13: 89 | P13: 89 | Q13: 76 | R13: 76 | S13: 76 | T13: 68 | U13: 0 | V13: 13039 | W13: Aluminium ohne Folie | X13: Al 99,5 % hh | Y13: EN AW-1050A H24 | Z13: 2,7 g/cm³ | AA13: 60,00 % | AB13: 3,38 Kg | AC13: 791 | AF13: Ohne besondere Oberflächenbearbeitung.
A14: streckmetall-tafelware-20x10x2 | B14: Streckgitter | C14: 20x10x2 | D14: Edelstahl (V2A) | E14: 1,00 mm | F14: Kleinformat (1000 x 2000 mm) | G14: https://cdn.shopify.com/s/files/1/0575/0797/1253/files/Streckmetall_Raute_20x10x2.jpg?v=1723045158 | H14: https://cdn.shopify.com/s/files/1/0575/0797/1253/files/20-10-2.pdf?v=1723206888 | I14: // | J14: (ohne Folie) | K14: 172 | L14: 155 | M14: 138 | N14: 128 | O14: 116 | P14: 116 | Q14: 106 | R14: 106 | S14: 106 | T14: 93 | U14: 0 | V14: 13045 | W14: Edelstahl (V2A) | X14: 1.4301 | Y14: X5CrNi18-10 | Z14: 8 g/cm³ | AA14: 60,00 % | AB14: 6,40 Kg | AC14: 791 | AF14: Ohne besondere Oberflächenbearbeitung.
A15: streckmetall-tafelware-20x10x2 | B15: Streckgitter | C15: 20x10x2 | D15: Stahl (verzinkt) | E15: 1,00 mm | F15: Kleinformat (1000 x 2000 mm) | G15: https://cdn.shopify.com/s/files/1/0575/0797/1253/files/Streckmetall_Raute_20x10x2.jpg?v=1723045158 | H15: https://cdn.shopify.com/s/files/1/0575/0797/1253/files/20-10-2.pdf?v=1723206888 | I15: // | K15: 101 | L15: 87 | M15: 75 | N15: 63 | O15: 55 | P15: 55 | Q15: 48 | R15: 48 | S15: 48 | T15: 40 | U15: 0 | V15: 13030 | W15: Sendzimir (verzinkt) | X15: St 02 Z 140 | Y15: DX51D+Z 140 | Z15: 8 g/cm³ | AA15: 60,00 % | AB15: 6,40 Kg | AC15: 791 | AF15: Wir weisen darauf hin, dass diese Zinkauflage im Außenbereich keinen ausreichenden und dauerhaften Korrosionsschutz gewährt.
A16: streckmetall-tafelware-20x10x2 | B16: Streckgitter | C16: 20x10x2 | D16: Stahl | E16: 1,00 mm | F16: Kleinformat (1000 x 2000 mm) | G16: https://cdn.shopify.com/s/files/1/0575/0797/1253/files/Streckmetall_Raute_20x10x2.jpg?v=1723045158 | H16: https://cdn.shopify.com/s/files/1/0575/0797/1253/files/20-10-2.pdf?v=1723206888 | I16: // | K16: 99 | L16: 85 | M16: 73 | N16: 61 | O16: 53 | P16: 53 | Q16: 46 | R16: 46 | S16: 46 | T16: 40 | U16: 0 | V16: 13022 | W16: Stahl | X16: StW 22 | Y16: DD 11 | Z16: 8 g/cm³ | AA16: 60,00 % | AB16: 6,40 Kg | AC16: 791 | AF16: Ohne besondere Oberflächenbearbeitung.
A17: =VLOOKUP(V17,SVERWEIS!A:B,2,FALSE) -> streckmetall-tafelware-20x10x2 | B17: Streckgitter | C17: 20x10x2 | D17: Stahl | E17: 1,00 mm | F17: Mittelformat (1250 x 2500 mm) | G17: https://cdn.shopify.com/s/files/1/0575/0797/1253/files/Streckmetall_Raute_20x10x2.jpg?v=1723045158 | H17: https://cdn.shopify.com/s/files/1/0575/0797/1253/files/20-10-2.pdf?v=1723206888 | I17: // | K17: 155 | L17: 115 | M17: 96 | N17: 84 | O17: 73 | P17: 73 | Q17: 62 | R17: 62 | S17: 62 | T17: 54 | U17: 0 | V17: 13025 | W17: Stahl | X17: StW 22 | Y17: DD 11 | Z17: 8 g/cm³ | AA17: 60,00 % | AB17: 10,00 Kg | AC17: 791 | AF17: Ohne besondere Oberflächenbearbeitung.
A18: =VLOOKUP(V18,SVERWEIS!A:B,2,FALSE) -> streckmetall-tafelware-20x10x2 | B18: Streckgitter | C18: 20x10x2 | D18: Stahl | E18: 1,00 mm | F18: Großformat (1500 x 3000 mm) | G18: https://cdn.shopify.com/s/files/1/0575/0797/1253/files/Streckmetall_Raute_20x10x2.jpg?v=1723045158 | H18: https://cdn.shopify.com/s/files/1/0575/0797/1253/files/20-10-2.pdf?v=1723206888 | I18: // | K18: 193 | L18: 140 | M18: 121 | N18: 106 | O18: 91 | P18: 91 | Q18: 78 | R18: 78 | S18: 78 | T18: 67 | U18: 0 | V18: 13028 | W18: Stahl | X18: StW 22 | Y18: DD 11 | Z18: 8 g/cm³ | AA18: 60,00 % | AB18: 14,40 Kg | AC18: 791 | AF18: Ohne besondere Oberflächenbearbeitung.
A19: streckmetall-tafelware-28x13x2 | B19: Streckgitter | C19: 28x13x2 | D19: Aluminium | E19: 2,00 mm | F19: Kleinformat (1000 x 2000 mm) | G19: https://cdn.shopify.com/s/files/1/0575/0797/1253/files/Streckmetall_Raute_28x13x2_jpg.jpg?v=1723045158 | H19: https://cdn.shopify.com/s/files/1/0575/0797/1253/files/28-13-2.pdf?v=1723206888 | I19: // | J19: (ohne Folie) | K19: 277 | L19: 185 | M19: 162 | N19: 133 | O19: 122 | P19: 122 | Q19: 100 | R19: 100 | S19: 100 | T19: 89 | U19: 0 | V19: 13141 | W19: Aluminium ohne Folie | X19: Al 99,5 % hh | Y19: EN AW-1050A H24 | Z19: 2,7 g/cm³ | AA19: 69,00 % | AB19: 3,35 Kg | AC19: 791 | AF19: Ohne besondere Oberflächenbearbeitung.
A20: =VLOOKUP(V20,SVERWEIS!A:B,2,FALSE) -> streckmetall-tafelware-28x13x2 | B20: Streckgitter | C20: 28x13x2 | D20: Aluminium | E20: 2,00 mm | F20: Mittelformat (1250 x 2500 mm) | G20: https://cdn.shopify.com/s/files/1/0575/0797/1253/files/Streckmetall_Raute_28x13x2_jpg.jpg?v=1723045158 | H20: https://cdn.shopify.com/s/files/1/0575/0797/1253/files/28-13-2.pdf?v=1723206888 | I20: // | J20: (ohne Folie) | K20: 433 | L20: 254 | M20: 209 | N20: 189 | O20: 157 | P20: 157 | Q20: 139 | R20: 139 | S20: 139 | T20: 119 | U20: 0 | V20: 13124 | W20: Aluminium ohne Folie | X20: Al 99,5 % hh | Y20: EN AW-1050A H24 | Z20: 2,7 g/cm³ | AA20: 69,00 % | AB20: 5,23 Kg | AC20: 791 | AF20: Ohne besondere Oberflächenbearbeitung.
A21: =VLOOKUP(V21,SVERWEIS!A:B,2,FALSE) -> streckmetall-tafelware-28x13x2 | B21: Streckgitter | C21: 28x13x2 | D21: Aluminium | E21: 2,00 mm | F21: Großformat (1500 x 3000 mm) | G21: https://cdn.shopify.com/s/files/1/0575/0797/1253/files/Streckmetall_Raute_28x13x2_jpg.jpg?v=1723045158 | H21: https://cdn.shopify.com/s/files/1/0575/0797/1253/files/28-13-2.pdf?v=1723206888 | I21: // | J21: (ohne Folie) | K21: 467 | L21: 302 | M21: 274 | N21: 226 | O21: 202 | P21: 202 | Q21: 173 | R21: 173 | S21: 173 | T21: 142 | U21: 0 | V21: 13127 | W21: Aluminium ohne Folie | X21: Al 99,5 % hh | Y21: EN AW-1050A H24 | Z21: 2,7 g/cm³ | AA21: 69,00 % | AB21: 7,53 Kg | AC21: 791 | AF21: Ohne besondere Oberflächenbearbeitung.
A22: streckmetall-tafelware-28x13x2 | B22: Streckgitter | C22: 28x13x2 | D22: Edelstahl (V2A) | E22: 1,00 mm | F22: Kleinformat (1000 x 2000 mm) | G22: https://cdn.shopify.com/s/files/1/0575/0797/1253/files/Streckmetall_Raute_28x13x2_jpg.jpg?v=1723045158 | H22: https://cdn.shopify.com/s/files/1/0575/0797/1253/files/28-13-2.pdf?v=1723206888 | I22: // | J22: (ohne Folie) | K22: 252 | L22: 206 | M22: 173 | N22: 144 | O22: 126 | P22: 126 | Q22: 112 | R22: 112 | S22: 112 | T22: 98 | U22: 0 | V22: 13128 | W22: Edelstahl (V2A) | X22: 1.4301 | Y22: X5CrNi18-10 | Z22: 8 g/cm³ | AA22: 69,00 % | AB22: 4,96 Kg | AC22: 791 | AF22: Ohne besondere Oberflächenbearbeitung.
A23: streckmetall-tafelware-28x13x2 | B23: Streckgitter | C23: 28x13x2 | D23: Edelstahl (V2A) | E23: 1,50 mm | F23: Kleinformat (1000 x 2000 mm) | G23: https://cdn.shopify.com/s/files/1/0575/0797/1253/files/Streckmetall_Raute_28x13x2_jpg.jpg?v=1723045158 | H23: https://cdn.shopify.com/s/files/1/0575/0797/1253/files/28-13-2.pdf?v=1723206888 | I23: // | J23: (ohne Folie) | K23: 273 | L23: 232 | M23: 198 | N23: 170 | O23: 152 | P23: 152 | Q23: 137 | R23: 137 | S23: 137 | T23: 121 | U23: 0 | V23: 5104 | W23: Edelstahl (V2A) | X23: 1.4301 | Y23: X5CrNi18-10 | Z23: 8 g/cm³ | AA23: 69,00 % | AB23: 7,44 Kg | AC23: 791 | AF23: Ohne besondere Oberflächenbearbeitung.
A24: streckmetall-tafelware-28x13x2 | B24: Streckgitter | C24: 28x13x2 | D24: Stahl | E24: 1,50 mm | F24: Kleinformat (1000 x 2000 mm) | G24: https://cdn.shopify.com/s/files/1/0575/0797/1253/files/Streckmetall_Raute_28x13x2_jpg.jpg?v=1723045158 | H24: https://cdn.shopify.com/s/files/1/0575/0797/1253/files/28-13-2.pdf?v=1723206888 | I24: // | K24: 114 | L24: 102 | M24: 92 | N24: 73 | O24: 63 | P24: 63 | Q24: 56 | R24: 56 | S24: 56 | T24: 52 | U24: 0 | V24: 13122 | W24: Stahl | X24: StW 22 | Y24: DD 11 | Z24: 8 g/cm³ | AA24: 69,00 % | AB24: 7,44 Kg | AC24: 791 | AF24: Ohne besondere Oberflächenbearbeitung.
A25: streckmetall-tafelware-28x13x2 | B25: Streckgitter | C25: 28x13x2 | D25: Stahl | E25: 2,00 mm | F25: Kleinformat (1000 x 2000 mm) | G25: https://cdn.shopify.com/s/files/1/0575/0797/1253/files/Streckmetall_Raute_28x13x2_jpg.jpg?v=1723045158 | H25: https://cdn.shopify.com/s/files/1/0575/0797/1253/files/28-13-2.pdf?v=1723206888 | I25: // | K25: 121 | L25: 109 | M25: 98 | N25: 79 | O25: 70 | P25: 70 | Q25: 63 | R25: 63 | S25: 63 | T25: 58 | U25: 0 | V25: 13123 | W25: Stahl | X25: StW 22 | Y25: DD 11 | Z25: 8 g/cm³ | AA25: 69,00 % | AB25: 9,92 Kg | AC25: 791 | AF25: Ohne besondere Oberflächenbearbeitung.
A26: =VLOOKUP(V26,SVERWEIS!A:B,2,FALSE) -> streckmetall-tafelware-28x13x2 | B26: Streckgitter | C26: 28x13x2 | D26: Stahl | E26: 2,00 mm | F26: Mittelformat (1250 x 2500 mm) | G26: https://cdn.shopify.com/s/files/1/0575/0797/1253/files/Streckmetall_Raute_28x13x2_jpg.jpg?v=1723045158 | H26: https://cdn.shopify.com/s/files/1/0575/0797/1253/files/28-13-2.pdf?v=1723206888 | I26: // | K26: 190 | L26: 155 | M26: 124 | N26: 110 | O26: 99 | P26: 99 | Q26: 92 | R26: 92 | S26: 92 | T26: 77 | U26: 0 | V26: 13131 | W26: Stahl | X26: StW 22 | Y26: DD 11 | Z26: 8 g/cm³ | AA26: 69,00 % | AB26: 15,50 Kg | AC26: 791 | AF26: Ohne besondere Oberflächenbearbeitung.
A27: =VLOOKUP(V27,SVERWEIS!A:B,2,FALSE) -> streckmetall-tafelware-28x13x2 | B27: Streckgitter | C27: 28x13x2 | D27: Stahl | E27: 2,00 mm | F27: Großformat (1500 x 3000 mm) | G27: https://cdn.shopify.com/s/files/1/0575/0797/1253/files/Streckmetall_Raute_28x13x2_jpg.jpg?v=1723045158 | H27: https://cdn.shopify.com/s/files/1/0575/0797/1253/files/28-13-2.pdf?v=1723206888 | I27: // | K27: 246 | L27: 180 | M27: 159 | N27: 143 | O27: 133 | P27: 133 | Q27: 111 | R27: 111 | S27: 111 | T27: 90 | U27: 0 | V27: 13144 | W27: Stahl | X27: StW 22 | Y27: DD 11 | Z27: 8 g/cm³ | AA27: 69,00 % | AB27: 22,32 Kg | AC27: 791 | AF27: Ohne besondere Oberflächenbearbeitung.
A28: streckmetall-tafelware-43x10x2-5 | B28: Streckgitter | C28: 43x10x2,5 | D28: Aluminium | E28: 2,00 mm | F28: Kleinformat (1000 x 2000 mm) | G28: https://cdn.shopify.com/s/files/1/0575/0797/1253/files/Streckmetall_Raute_43x10x2_5.jpg?v=1723207955 | H28: https://cdn.shopify.com/s/files/1/0575/0797/1253/files/43-10-2_5.pdf?v=1723206887 | I28: // | J28: (ohne Folie) | K28: 280 | L28: 187 | M28: 165 | N28: 136 | O28: 123 | P28: 123 | Q28: 102 | R28: 102 | S28: 102 | T28: 91 | U28: 0 | V28: 13244 | W28: Aluminium ohne Folie | X28: Al 99,5 % hh | Y28: EN AW-1050A H24 | Z28: 2,7 g/cm³ | AA28: 50,00 % | AB28: 5,40 Kg | AC28: 791 | AF28: Ohne besondere Oberflächenbearbeitung.
A29: =VLOOKUP(V29,SVERWEIS!A:B,2,FALSE) -> streckmetall-tafelware-43x10x2-5 | B29: Streckgitter | C29: 43x10x2,5 | D29: Aluminium | E29: 2,00 mm | F29: Mittelformat (1250 x 2500 mm) | G29: https://cdn.shopify.com/s/files/1/0575/0797/1253/files/Streckmetall_Raute_43x10x2_5.jpg?v=1723207955 | H29: https://cdn.shopify.com/s/files/1/0575/0797/1253/files/43-10-2_5.pdf?v=1723206887 | I29: // | J29: (ohne Folie) | K29: 437 | L29: 285 | M29: 213 | N29: 194 | O29: 161 | P29: 161 | Q29: 144 | R29: 144 | S29: 144 | T29: 124 | U29: 0 | V29: 13227 | W29: Aluminium ohne Folie | X29: Al 99,5 % hh | Y29: EN AW-1050A H24 | Z29: 2,7 g/cm³ | AA29: 50,00 % | AB29: 8,44 Kg | AC29: 791 | AF29: Ohne besondere Oberflächenbearbeitung.
A30: =VLOOKUP(V30,SVERWEIS!A:B,2,FALSE) -> streckmetall-tafelware-43x10x2-5 | B30: Streckgitter | C30: 43x10x2,5 | D30: Aluminium | E30: 2,00 mm | F30: Großformat (1500 x 3000 mm) | G30: https://cdn.shopify.com/s/files/1/0575/0797/1253/files/Streckmetall_Raute_43x10x2_5.jpg?v=1723207955 | H30: https://cdn.shopify.com/s/files/1/0575/0797/1253/files/43-10-2_5.pdf?v=1723206887 | I30: // | J30: (ohne Folie) | K30: 470 | L30: 308 | M30: 280 | N30: 232 | O30: 208 | P30: 208 | Q30: 179 | R30: 179 | S30: 179 | T30: 149 | U30: 0 | V30: 13230 | W30: Aluminium ohne Folie | X30: Al 99,5 % hh | Y30: EN AW-1050A H24 | Z30: 2,7 g/cm³ | AA30: 50,00 % | AB30: 12,15 Kg | AC30: 791 | AF30: Ohne besondere Oberflächenbearbeitung.
A31: streckmetall-tafelware-43x10x2-5 | B31: Streckgitter | C31: 43x10x2,5 | D31: Edelstahl (V2A) | E31: 1,00 mm | F31: Kleinformat (1000 x 2000 mm) | G31: https://cdn.shopify.com/s/files/1/0575/0797/1253/files/Streckmetall_Raute_43x10x2_5.jpg?v=1723207955 | H31: https://cdn.shopify.com/s/files/1/0575/0797/1253/files/43-10-2_5.pdf?v=1723206887 | I31: // | J31: (ohne Folie) | K31: 256 | L31: 210 | M31: 176 | N31: 148 | O31: 130 | P31: 130 | Q31: 115 | R31: 115 | S31: 115 | T31: 101 | U31: 0 | V31: 13231 | W31: Edelstahl (V2A) | X31: 1.4301 | Y31: X5CrNi18-10 | Z31: 8 g/cm³ | AA31: 50,00 % | AB31: 8,00 Kg | AC31: 791 | AF31: Ohne besondere Oberflächenbearbeitung.
A32: streckmetall-tafelware-43x10x2-5 | B32: Streckgitter | C32: 43x10x2,5 | D32: Edelstahl (V2A) | E32: 1,50 mm | F32: Kleinformat (1000 x 2000 mm) | G32: https://cdn.shopify.com/s/files/1/0575/0797/1253/files/Streckmetall_Raute_43x10x2_5.jpg?v=1723207955 | H32: https://cdn.shopify.com/s/files/1/0575/0797/1253/files/43-10-2_5.pdf?v=1723206887 | I32: // | J32: (ohne Folie) | K32: 283 | L32: 237 | M32: 203 | N32: 175 | O32: 157 | P32: 157 | Q32: 143 | R32: 143 | S32: 143 | T32: 126 | U32: 0 | V32: 13223 | W32: Edelstahl (V2A) | X32: 1.4301 | Y32: X5CrNi18-10 | Z32: 8 g/cm³ | AA32: 50,00 % | AB32: 12,00 Kg | AC32: 791 | AF32: Ohne besondere Oberflächenbearbeitung.
A33: streckmetall-tafelware-43x10x2-5 | B33: Streckgitter | C33: 43x10x2,5 | D33: Stahl (verzinkt) | E33: 1,50 mm | F33: Kleinformat (1000 x 2000 mm) | G33: https://cdn.shopify.com/s/files/1/0575/0797/1253/files/Streckmetall_Raute_43x10x2_5.jpg?v=1723207955 | H33: https://cdn.shopify.com/s/files/1/0575/0797/1253/files/43-10-2_5.pdf?v=1723206887 | I33: // | K33: 220 | L33: 146 | M33: 125 | N33: 103 | O33: 86 | P33: 86 | Q33: 75 | R33: 75 | S33: 75 | T33: 66 | U33: 0 | V33: 13243 | W33: Sendzimir (verzinkt) | X33: St 02 Z 140 | Y33: DX51D+Z 140 | Z33: 8 g/cm³ | AA33: 50,00 % | AB33: 12,00 Kg | AC33: 791 | AF33: Wir weisen darauf hin, dass diese Zinkauflage im Außenbereich keinen ausreichenden und dauerhaften Korrosionsschutz gewährt.
A34: =VLOOKUP(V34,SVERWEIS!A:B,2,FALSE) -> streckmetall-tafelware-43x10x2-5 | B34: Streckgitter | C34: 43x10x2,5 | D34: Stahl (verzinkt) | E34: 1,50 mm | F34: Mittelformat (1250 x 2500 mm) | G34: https://cdn.shopify.com/s/files/1/0575/0797/1253/files/Streckmetall_Raute_43x10x2_5.jpg?v=1723207955 | H34: https://cdn.shopify.com/s/files/1/0575/0797/1253/files/43-10-2_5.pdf?v=1723206887 | I34: // | K34: 351 | L34: 201 | M34: 166 | N34: 139.5 | O34: 121 | P34: 121 | Q34: 106 | R34: 106 | S34: 106 | T34: 93 | U34: 0 | V34: 13240 | W34: Sendzimir (verzinkt) | X34: St 02 Z 140 | Y34: DX51D+Z 140 | Z34: 8 g/cm³ | AA34: 50,00 % | AB34: 18,75 Kg | AC34: 791 | AF34: Wir weisen darauf hin, dass diese Zinkauflage im Außenbereich keinen ausreichenden und dauerhaften Korrosionsschutz gewährt.
A35: streckmetall-tafelware-43x10x2-5 | B35: Streckgitter | C35: 43x10x2,5 | D35: Stahl | E35: 2,00 mm | F35: Kleinformat (1000 x 2000 mm) | G35: https://cdn.shopify.com/s/files/1/0575/0797/1253/files/Streckmetall_Raute_43x10x2_5.jpg?v=1723207955 | H35: https://cdn.shopify.com/s/files/1/0575/0797/1253/files/43-10-2_5.pdf?v=1723206887 | I35: // | K35: 123 | L35: 111 | M35: 101 | N35: 81 | O35: 72 | P35: 72 | Q35: 68 | R35: 68 | S35: 68 | T35: 60 | U35: 0 | V35: 13226 | W35: Stahl | X35: StW 22 | Y35: DD 11 | Z35: 8 g/cm³ | AA35: 50,00 % | AB35: 16,00 Kg | AC35: 791 | AF35: Ohne besondere Oberflächenbearbeitung.
A36: =VLOOKUP(V36,SVERWEIS!A:B,2,FALSE) -> streckmetall-tafelware-43x10x2-5 | B36: Streckgitter | C36: 43x10x2,5 | D36: Stahl | E36: 2,00 mm | F36: Mittelformat (1250 x 2500 mm) | G36: https://cdn.shopify.com/s/files/1/0575/0797/1253/files/Streckmetall_Raute_43x10x2_5.jpg?v=1723207955 | H36: https://cdn.shopify.com/s/files/1/0575/0797/1253/files/43-10-2_5.pdf?v=1723206887 | I36: // | K36: 193 | L36: 158 | M36: 128 | N36: 113 | O36: 102 | P36: 102 | Q36: 95 | R36: 95 | S36: 95 | T36: 80 | U36: 0 | V36: 13234 | W36: Stahl | X36: StW 22 | Y36: DD 11 | Z36: 8 g/cm³ | AA36: 50,00 % | AB36: 25,00 Kg | AC36: 791 | AF36: Ohne besondere Oberflächenbearbeitung.
A37: streckmetall-tafelware-62x20x7-5 | B37: Streckgitter | C37: 62x20x7,5 | D37: Aluminium | E37: 2,00 mm | F37: Kleinformat (1000 x 2000 mm) | G37: https://cdn.shopify.com/s/files/1/0575/0797/1253/files/Streckmetall_Raute_62x20x7_5.jpg?v=1723045158 | H37: https://cdn.shopify.com/s/files/1/0575/0797/1253/files/62-20-7_5.pdf?v=1723206888 | I37: // | J37: (ohne Folie) | K37: 287 | L37: 195 | M37: 173 | N37: 144 | O37: 131 | P37: 131 | Q37: 110 | R37: 110 | S37: 110 | T37: 99 | U37: 0 | V37: 14039 | W37: Aluminium ohne Folie | X37: Al 99,5 % hh | Y37: EN AW-1050A H24 | Z37: 2,7 g/cm³ | AA37: 25,00 % | AB37: 8,10 Kg | AC37: 791 | AF37: Ohne besondere Oberflächenbearbeitung.
A38: =VLOOKUP(V38,SVERWEIS!A:B,2,FALSE) -> streckmetall-tafelware-62x20x7-5 | B38: Streckgitter | C38: 62x20x7,5 | D38: Aluminium | E38: 2,00 mm | F38: Mittelformat (1250 x 2500 mm) | G38: https://cdn.shopify.com/s/files/1/0575/0797/1253/files/Streckmetall_Raute_62x20x7_5.jpg?v=1723045158 | H38: https://cdn.shopify.com/s/files/1/0575/0797/1253/files/62-20-7_5.pdf?v=1723206888 | I38: // | J38: (ohne Folie) | K38: 450 | L38: 271 | M38: 225 | N38: 206 | O38: 173 | P38: 173 | Q38: 156 | R38: 156 | S38: 156 | T38: 136 | U38: 0 | V38: 14038 | W38: Aluminium ohne Folie | X38: Al 99,5 % hh | Y38: EN AW-1050A H24 | Z38: 2,7 g/cm³ | AA38: 25,00 % | AB38: 12,66 Kg | AC38: 791 | AF38: Ohne besondere Oberflächenbearbeitung.
A39: =VLOOKUP(V39,SVERWEIS!A:B,2,FALSE) -> streckmetall-tafelware-62x20x7-5 | B39: Streckgitter | C39: 62x20x7,5 | D39: Aluminium | E39: 2,00 mm | F39: Großformat (1500 x 3000 mm) | G39: https://cdn.shopify.com/s/files/1/0575/0797/1253/files/Streckmetall_Raute_62x20x7_5.jpg?v=1723045158 | H39: https://cdn.shopify.com/s/files/1/0575/0797/1253/files/62-20-7_5.pdf?v=1723206888 | I39: // | J39: (ohne Folie) | K39: 489 | L39: 326 | M39: 298 | N39: 250 | O39: 226 | P39: 226 | Q39: 197 | R39: 197 | S39: 197 | T39: 166 | U39: 0 | V39: 14037 | W39: Aluminium ohne Folie | X39: Al 99,5 % hh | Y39: EN AW-1050A H24 | Z39: 2,7 g/cm³ | AA39: 25,00 % | AB39: 18,23 Kg | AC39: 791 | AF39: Ohne besondere Oberflächenbearbeitung.
A40: streckmetall-tafelware-62x20x7-5 | B40: Streckgitter | C40: 62x20x7,5 | D40: Stahl (verzinkt) | E40: 1,50 mm | F40: Kleinformat (1000 x 2000 mm) | G40: https://cdn.shopify.com/s/files/1/0575/0797/1253/files/Streckmetall_Raute_62x20x7_5.jpg?v=1723045158 | H40: https://cdn.shopify.com/s/files/1/0575/0797/1253/files/62-20-7_5.pdf?v=1723206888 | I40: // | K40: 225 | L40: 151 | M40: 130 | N40: 108 | O40: 92 | P40: 92 | Q40: 80 | R40: 80 | S40: 80 | T40: 71 | U40: 0 | V40: 14050 | W40: Sendzimir (verzinkt) | X40: St 02 Z 140 | Y40: DX51D+Z 140 | Z40: 8 g/cm³ | AA40: 25,00 % | AB40: 18,00 Kg | AC40: 791 | AF40: Wir weisen darauf hin, dass diese Zinkauflage im Außenbereich keinen ausreichenden und dauerhaften Korrosionsschutz gewährt.
...

Sheet SVERWEIS
A1: 15774 | B1: lochblech-tafelware-quadratlochung-gerade-qg-4-194
A2: 363 | B2: lochblech-tafelware-quadratlochung-gerade-qg-5-8
A3: 366 | B3: lochblech-tafelware-quadratlochung-gerade-qg-5-8
A4: 367 | B4: lochblech-tafelware-quadratlochung-gerade-qg-5-8
A5: 356 | B5: lochblech-tafelware-quadratlochung-gerade-qg-5-8
A6: 357 | B6: lochblech-tafelware-quadratlochung-gerade-qg-5-8
A7: 358 | B7: lochblech-tafelware-quadratlochung-gerade-qg-5-8
A8: 359 | B8: lochblech-tafelware-quadratlochung-gerade-qg-5-8
A9: 360 | B9: lochblech-tafelware-quadratlochung-gerade-qg-5-8
A10: 797 | B10: lochblech-tafelware-quadratlochung-gerade-qg-5-16
A11: 537 | B11: lochblech-tafelware-quadratlochung-gerade-qg-5-16
A12: 5141 | B12: lochblech-tafelware-quadratlochung-gerade-qg-5-16
... A250: 15758 | B250: kunststoff-lochplatte-tafelware-qg-20-25-aus-pvc
B251: kunststoff-lochplatte-tafelware-qg-20-25-aus-pvc
A252: 15765 | B252: kunststoff-lochplatte-tafelware-rv-6-14-aus-pvc
A253: 15764 | B253: kunststoff-lochplatte-tafelware-rv-6-14-aus-pvc
B254: kunststoff-lochplatte-tafelware-rv-6-14-aus-pvc
A255: 15768 | B255: kunststoff-lochplatte-tafelware-rv-20-28-aus-pvc
A256: 15767 | B256: kunststoff-lochplatte-tafelware-rv-20-28-aus-pvc
B257: kunststoff-lochplatte-tafelware-rv-20-28-aus-pvc
A258: 940 | B258: lochblech-tafelware-quadratlochung-gerade-qg-5-16
A259: 1062 | B259: lochblech-tafelware-quadratlochung-gerade-qg-5-16
A260: 846 | B260: lochblech-tafelware-quadratlochung-gerade-qg-5-16
A261: 376 | B261: lochblech-tafelware-quadratlochung-gerade-qg-5-16
A262: 5178 | B262: lochblech-tafelware-quadratlochung-gerade-qg-5-16
A263: 1840 | B263: lochblech-tafelware-quadratlochung-gerade-qg-5-16
A264: 5182 | B264: lochblech-tafelware-quadratlochung-gerade-qg-5-16
A265: 797 | B265: lochblech-tafelware-quadratlochung-gerade-qg-5-16
A266: 537 | B266: lochblech-tafelware-quadratlochung-gerade-qg-5-16
A267: 5120 | B267: lochblech-tafelware-quadratlochung-gerade-qg-5-16
A268: 795 | B268: lochblech-tafelware-quadratlochung-gerade-qg-5-16
A269: 1969 | B269: lochblech-tafelware-quadratlochung-gerade-qg-5-8
... A725: 12668 | B725: wellengitter-tafelware-wg-52-52
B726: daemmung-fuer-rippenheizkoerper
B727: daemmung-fuer-rippenheizkoerper
B728: daemmung-fuer-rippenheizkoerper
B729: daemmung-fuer-rippenheizkoerper
B730: daemmung-fuer-rippenheizkoerper
B731: daemmung-fuer-rippenheizkoerper
B732: daemmung-fuer-rippenheizkoerper
...
